{"errorMessage": "An error occurred (ValidationException) when calling the BatchWriteItem operation: The provided key element does not match the schema", "errorType": "ClientError", "stackTrace": ["  File \"/var/task/DbFill.py\", line 51, in lambda_handler\n    insert_data_batch(auftrag_table, auftrag_item)\n", "  File \"/var/task/DbFill.py\", line 16, in insert_data_batch\n    batch.put_item(Item=item)\n", "  File \"/var/runtime/boto3/dynamodb/table.py\", line 167, in __exit__\n    self._flush()\n", "  File \"/var/runtime/boto3/dynamodb/table.py\", line 144, in _flush\n    response = self._client.batch_write_item(\n", "  File \"/var/runtime/botocore/client.py\", line 530, in _api_call\n    return self._make_api_call(operation_name, kwargs)\n", "  File \"/var/runtime/botocore/client.py\", line 960, in _make_api_call\n    raise error_class(parsed_response, operation_name)\n"]}